2015-01-12 16:10:07 [4019] [ERROR] Exception in worker process:
Traceback (most recent call last):
  File "/usr/lib/python2.7/dist-packages/gunicorn/arbiter.py", line 473, in spawn_worker
    worker.init_process()
  File "/usr/lib/python2.7/dist-packages/gunicorn/workers/base.py", line 100, in init_process
    self.wsgi = self.app.wsgi()
  File "/usr/lib/python2.7/dist-packages/gunicorn/app/base.py", line 115, in wsgi
    self.callable = self.load()
  File "/usr/lib/python2.7/dist-packages/gunicorn/app/wsgiapp.py", line 33, in load
    return util.import_app(self.app_uri)
  File "/usr/lib/python2.7/dist-packages/gunicorn/util.py", line 362, in import_app
    __import__(module)
  File "/home/js345/yumbon/cteemo/flask-user-api/app.py", line 51, in <module>
    @app.errorhandler(InvalidAPIUsage)
NameError: name 'InvalidAPIUsage' is not defined
Traceback (most recent call last):
  File "/usr/lib/python2.7/dist-packages/gunicorn/arbiter.py", line 473, in spawn_worker
    worker.init_process()
  File "/usr/lib/python2.7/dist-packages/gunicorn/workers/base.py", line 100, in init_process
    self.wsgi = self.app.wsgi()
  File "/usr/lib/python2.7/dist-packages/gunicorn/app/base.py", line 115, in wsgi
    self.callable = self.load()
  File "/usr/lib/python2.7/dist-packages/gunicorn/app/wsgiapp.py", line 33, in load
    return util.import_app(self.app_uri)
  File "/usr/lib/python2.7/dist-packages/gunicorn/util.py", line 362, in import_app
    __import__(module)
  File "/home/js345/yumbon/cteemo/flask-user-api/app.py", line 51, in <module>
    @app.errorhandler(InvalidAPIUsage)
NameError: name 'InvalidAPIUsage' is not defined
2015-01-12 16:10:07 [4022] [ERROR] Exception in worker process:
Traceback (most recent call last):
  File "/usr/lib/python2.7/dist-packages/gunicorn/arbiter.py", line 473, in spawn_worker
    worker.init_process()
  File "/usr/lib/python2.7/dist-packages/gunicorn/workers/base.py", line 100, in init_process
    self.wsgi = self.app.wsgi()
  File "/usr/lib/python2.7/dist-packages/gunicorn/app/base.py", line 115, in wsgi
    self.callable = self.load()
  File "/usr/lib/python2.7/dist-packages/gunicorn/app/wsgiapp.py", line 33, in load
    return util.import_app(self.app_uri)
  File "/usr/lib/python2.7/dist-packages/gunicorn/util.py", line 362, in import_app
    __import__(module)
  File "/home/js345/yumbon/cteemo/flask-user-api/app.py", line 51, in <module>
    @app.errorhandler(InvalidAPIUsage)
NameError: name 'InvalidAPIUsage' is not defined
Traceback (most recent call last):
  File "/usr/lib/python2.7/dist-packages/gunicorn/arbiter.py", line 473, in spawn_worker
    worker.init_process()
  File "/usr/lib/python2.7/dist-packages/gunicorn/workers/base.py", line 100, in init_process
    self.wsgi = self.app.wsgi()
  File "/usr/lib/python2.7/dist-packages/gunicorn/app/base.py", line 115, in wsgi
    self.callable = self.load()
  File "/usr/lib/python2.7/dist-packages/gunicorn/app/wsgiapp.py", line 33, in load
    return util.import_app(self.app_uri)
  File "/usr/lib/python2.7/dist-packages/gunicorn/util.py", line 362, in import_app
    __import__(module)
  File "/home/js345/yumbon/cteemo/flask-user-api/app.py", line 51, in <module>
    @app.errorhandler(InvalidAPIUsage)
NameError: name 'InvalidAPIUsage' is not defined
2015-01-12 16:10:07 [4023] [ERROR] Exception in worker process:
Traceback (most recent call last):
  File "/usr/lib/python2.7/dist-packages/gunicorn/arbiter.py", line 473, in spawn_worker
    worker.init_process()
  File "/usr/lib/python2.7/dist-packages/gunicorn/workers/base.py", line 100, in init_process
    self.wsgi = self.app.wsgi()
  File "/usr/lib/python2.7/dist-packages/gunicorn/app/base.py", line 115, in wsgi
    self.callable = self.load()
  File "/usr/lib/python2.7/dist-packages/gunicorn/app/wsgiapp.py", line 33, in load
    return util.import_app(self.app_uri)
  File "/usr/lib/python2.7/dist-packages/gunicorn/util.py", line 362, in import_app
    __import__(module)
  File "/home/js345/yumbon/cteemo/flask-user-api/app.py", line 51, in <module>
    @app.errorhandler(InvalidAPIUsage)
NameError: name 'InvalidAPIUsage' is not defined
Traceback (most recent call last):
  File "/usr/lib/python2.7/dist-packages/gunicorn/arbiter.py", line 473, in spawn_worker
    worker.init_process()
  File "/usr/lib/python2.7/dist-packages/gunicorn/workers/base.py", line 100, in init_process
    self.wsgi = self.app.wsgi()
  File "/usr/lib/python2.7/dist-packages/gunicorn/app/base.py", line 115, in wsgi
    self.callable = self.load()
  File "/usr/lib/python2.7/dist-packages/gunicorn/app/wsgiapp.py", line 33, in load
    return util.import_app(self.app_uri)
  File "/usr/lib/python2.7/dist-packages/gunicorn/util.py", line 362, in import_app
    __import__(module)
  File "/home/js345/yumbon/cteemo/flask-user-api/app.py", line 51, in <module>
    @app.errorhandler(InvalidAPIUsage)
NameError: name 'InvalidAPIUsage' is not defined
2015-01-12 16:10:07 [4028] [ERROR] Exception in worker process:
Traceback (most recent call last):
  File "/usr/lib/python2.7/dist-packages/gunicorn/arbiter.py", line 473, in spawn_worker
    worker.init_process()
  File "/usr/lib/python2.7/dist-packages/gunicorn/workers/base.py", line 100, in init_process
    self.wsgi = self.app.wsgi()
  File "/usr/lib/python2.7/dist-packages/gunicorn/app/base.py", line 115, in wsgi
    self.callable = self.load()
  File "/usr/lib/python2.7/dist-packages/gunicorn/app/wsgiapp.py", line 33, in load
    return util.import_app(self.app_uri)
  File "/usr/lib/python2.7/dist-packages/gunicorn/util.py", line 362, in import_app
    __import__(module)
  File "/home/js345/yumbon/cteemo/flask-user-api/app.py", line 51, in <module>
    @app.errorhandler(InvalidAPIUsage)
NameError: name 'InvalidAPIUsage' is not defined
Traceback (most recent call last):
  File "/usr/lib/python2.7/dist-packages/gunicorn/arbiter.py", line 473, in spawn_worker
    worker.init_process()
  File "/usr/lib/python2.7/dist-packages/gunicorn/workers/base.py", line 100, in init_process
    self.wsgi = self.app.wsgi()
  File "/usr/lib/python2.7/dist-packages/gunicorn/app/base.py", line 115, in wsgi
    self.callable = self.load()
  File "/usr/lib/python2.7/dist-packages/gunicorn/app/wsgiapp.py", line 33, in load
    return util.import_app(self.app_uri)
  File "/usr/lib/python2.7/dist-packages/gunicorn/util.py", line 362, in import_app
    __import__(module)
  File "/home/js345/yumbon/cteemo/flask-user-api/app.py", line 51, in <module>
    @app.errorhandler(InvalidAPIUsage)
NameError: name 'InvalidAPIUsage' is not defined
2015-01-12 16:10:07 [4034] [ERROR] Exception in worker process:
Traceback (most recent call last):
  File "/usr/lib/python2.7/dist-packages/gunicorn/arbiter.py", line 473, in spawn_worker
    worker.init_process()
  File "/usr/lib/python2.7/dist-packages/gunicorn/workers/base.py", line 100, in init_process
    self.wsgi = self.app.wsgi()
  File "/usr/lib/python2.7/dist-packages/gunicorn/app/base.py", line 115, in wsgi
    self.callable = self.load()
  File "/usr/lib/python2.7/dist-packages/gunicorn/app/wsgiapp.py", line 33, in load
    return util.import_app(self.app_uri)
  File "/usr/lib/python2.7/dist-packages/gunicorn/util.py", line 362, in import_app
    __import__(module)
  File "/home/js345/yumbon/cteemo/flask-user-api/app.py", line 16, in <module>
    db.init_app(app)
  File "/usr/local/lib/python2.7/dist-packages/flask_mongoengine/__init__.py", line 66, in init_app
    self.connection = mongoengine.connect(**conn_settings)
  File "/usr/local/lib/python2.7/dist-packages/mongoengine/connection.py", line 161, in connect
    return get_connection(alias)
  File "/usr/local/lib/python2.7/dist-packages/mongoengine/connection.py", line 124, in get_connection
    raise ConnectionError("Cannot connect to database %s :\n%s" % (alias, e))
ConnectionError: Cannot connect to database default :
[Errno 4] Interrupted system call
Traceback (most recent call last):
  File "/usr/lib/python2.7/dist-packages/gunicorn/arbiter.py", line 473, in spawn_worker
    worker.init_process()
  File "/usr/lib/python2.7/dist-packages/gunicorn/workers/base.py", line 100, in init_process
    self.wsgi = self.app.wsgi()
  File "/usr/lib/python2.7/dist-packages/gunicorn/app/base.py", line 115, in wsgi
    self.callable = self.load()
  File "/usr/lib/python2.7/dist-packages/gunicorn/app/wsgiapp.py", line 33, in load
    return util.import_app(self.app_uri)
  File "/usr/lib/python2.7/dist-packages/gunicorn/util.py", line 362, in import_app
    __import__(module)
  File "/home/js345/yumbon/cteemo/flask-user-api/app.py", line 16, in <module>
    db.init_app(app)
  File "/usr/local/lib/python2.7/dist-packages/flask_mongoengine/__init__.py", line 66, in init_app
    self.connection = mongoengine.connect(**conn_settings)
  File "/usr/local/lib/python2.7/dist-packages/mongoengine/connection.py", line 161, in connect
    return get_connection(alias)
  File "/usr/local/lib/python2.7/dist-packages/mongoengine/connection.py", line 124, in get_connection
    raise ConnectionError("Cannot connect to database %s :\n%s" % (alias, e))
ConnectionError: Cannot connect to database default :
[Errno 4] Interrupted system call
2015-01-12 16:10:07 [4029] [ERROR] Exception in worker process:
Traceback (most recent call last):
  File "/usr/lib/python2.7/dist-packages/gunicorn/arbiter.py", line 473, in spawn_worker
    worker.init_process()
  File "/usr/lib/python2.7/dist-packages/gunicorn/workers/base.py", line 100, in init_process
    self.wsgi = self.app.wsgi()
  File "/usr/lib/python2.7/dist-packages/gunicorn/app/base.py", line 115, in wsgi
    self.callable = self.load()
  File "/usr/lib/python2.7/dist-packages/gunicorn/app/wsgiapp.py", line 33, in load
    return util.import_app(self.app_uri)
  File "/usr/lib/python2.7/dist-packages/gunicorn/util.py", line 362, in import_app
    __import__(module)
  File "/home/js345/yumbon/cteemo/flask-user-api/app.py", line 51, in <module>
    @app.errorhandler(InvalidAPIUsage)
NameError: name 'InvalidAPIUsage' is not defined
Traceback (most recent call last):
  File "/usr/lib/python2.7/dist-packages/gunicorn/arbiter.py", line 473, in spawn_worker
    worker.init_process()
  File "/usr/lib/python2.7/dist-packages/gunicorn/workers/base.py", line 100, in init_process
    self.wsgi = self.app.wsgi()
  File "/usr/lib/python2.7/dist-packages/gunicorn/app/base.py", line 115, in wsgi
    self.callable = self.load()
  File "/usr/lib/python2.7/dist-packages/gunicorn/app/wsgiapp.py", line 33, in load
    return util.import_app(self.app_uri)
  File "/usr/lib/python2.7/dist-packages/gunicorn/util.py", line 362, in import_app
    __import__(module)
  File "/home/js345/yumbon/cteemo/flask-user-api/app.py", line 51, in <module>
    @app.errorhandler(InvalidAPIUsage)
NameError: name 'InvalidAPIUsage' is not defined
Traceback (most recent call last):
  File "/usr/bin/gunicorn", line 9, in <module>
    load_entry_point('gunicorn==17.5', 'console_scripts', 'gunicorn')()
  File "/usr/lib/python2.7/dist-packages/gunicorn/app/wsgiapp.py", line 42, in run
    WSGIApplication("%(prog)s [OPTIONS] APP_MODULE").run()
  File "/usr/lib/python2.7/dist-packages/gunicorn/app/base.py", line 144, in run
    Arbiter(self).run()
  File "/usr/lib/python2.7/dist-packages/gunicorn/arbiter.py", line 196, in run
    self.halt(reason=inst.reason, exit_status=inst.exit_status)
  File "/usr/lib/python2.7/dist-packages/gunicorn/arbiter.py", line 291, in halt
    self.stop()
  File "/usr/lib/python2.7/dist-packages/gunicorn/arbiter.py", line 334, in stop
    self.reap_workers()
  File "/usr/lib/python2.7/dist-packages/gunicorn/arbiter.py", line 430, in reap_workers
    raise HaltServer(reason, self.WORKER_BOOT_ERROR)
gunicorn.errors.HaltServer: <HaltServer 'Worker failed to boot.' 3>
2015-01-12 16:10:07 [4037] [ERROR] Exception in worker process:
Traceback (most recent call last):
  File "/usr/lib/python2.7/dist-packages/gunicorn/arbiter.py", line 473, in spawn_worker
    worker.init_process()
  File "/usr/lib/python2.7/dist-packages/gunicorn/workers/base.py", line 100, in init_process
    self.wsgi = self.app.wsgi()
  File "/usr/lib/python2.7/dist-packages/gunicorn/app/base.py", line 115, in wsgi
    self.callable = self.load()
  File "/usr/lib/python2.7/dist-packages/gunicorn/app/wsgiapp.py", line 33, in load
    return util.import_app(self.app_uri)
  File "/usr/lib/python2.7/dist-packages/gunicorn/util.py", line 362, in import_app
    __import__(module)
  File "/home/js345/yumbon/cteemo/flask-user-api/app.py", line 51, in <module>
    @app.errorhandler(InvalidAPIUsage)
NameError: name 'InvalidAPIUsage' is not defined
Traceback (most recent call last):
  File "/usr/lib/python2.7/dist-packages/gunicorn/arbiter.py", line 473, in spawn_worker
    worker.init_process()
  File "/usr/lib/python2.7/dist-packages/gunicorn/workers/base.py", line 100, in init_process
    self.wsgi = self.app.wsgi()
  File "/usr/lib/python2.7/dist-packages/gunicorn/app/base.py", line 115, in wsgi
    self.callable = self.load()
  File "/usr/lib/python2.7/dist-packages/gunicorn/app/wsgiapp.py", line 33, in load
    return util.import_app(self.app_uri)
  File "/usr/lib/python2.7/dist-packages/gunicorn/util.py", line 362, in import_app
    __import__(module)
  File "/home/js345/yumbon/cteemo/flask-user-api/app.py", line 51, in <module>
    @app.errorhandler(InvalidAPIUsage)
NameError: name 'InvalidAPIUsage' is not defined
2015-01-12 16:10:07 [4038] [ERROR] Exception in worker process:
Traceback (most recent call last):
  File "/usr/lib/python2.7/dist-packages/gunicorn/arbiter.py", line 473, in spawn_worker
    worker.init_process()
  File "/usr/lib/python2.7/dist-packages/gunicorn/workers/base.py", line 100, in init_process
    self.wsgi = self.app.wsgi()
  File "/usr/lib/python2.7/dist-packages/gunicorn/app/base.py", line 115, in wsgi
    self.callable = self.load()
  File "/usr/lib/python2.7/dist-packages/gunicorn/app/wsgiapp.py", line 33, in load
    return util.import_app(self.app_uri)
  File "/usr/lib/python2.7/dist-packages/gunicorn/util.py", line 362, in import_app
    __import__(module)
  File "/home/js345/yumbon/cteemo/flask-user-api/app.py", line 51, in <module>
    @app.errorhandler(InvalidAPIUsage)
NameError: name 'InvalidAPIUsage' is not defined
Traceback (most recent call last):
  File "/usr/lib/python2.7/dist-packages/gunicorn/arbiter.py", line 473, in spawn_worker
    worker.init_process()
  File "/usr/lib/python2.7/dist-packages/gunicorn/workers/base.py", line 100, in init_process
    self.wsgi = self.app.wsgi()
  File "/usr/lib/python2.7/dist-packages/gunicorn/app/base.py", line 115, in wsgi
    self.callable = self.load()
  File "/usr/lib/python2.7/dist-packages/gunicorn/app/wsgiapp.py", line 33, in load
    return util.import_app(self.app_uri)
  File "/usr/lib/python2.7/dist-packages/gunicorn/util.py", line 362, in import_app
    __import__(module)
  File "/home/js345/yumbon/cteemo/flask-user-api/app.py", line 51, in <module>
    @app.errorhandler(InvalidAPIUsage)
NameError: name 'InvalidAPIUsage' is not defined
2015-01-12 16:10:07 [4039] [ERROR] Exception in worker process:
Traceback (most recent call last):
  File "/usr/lib/python2.7/dist-packages/gunicorn/arbiter.py", line 473, in spawn_worker
    worker.init_process()
  File "/usr/lib/python2.7/dist-packages/gunicorn/workers/base.py", line 100, in init_process
    self.wsgi = self.app.wsgi()
  File "/usr/lib/python2.7/dist-packages/gunicorn/app/base.py", line 115, in wsgi
    self.callable = self.load()
  File "/usr/lib/python2.7/dist-packages/gunicorn/app/wsgiapp.py", line 33, in load
    return util.import_app(self.app_uri)
  File "/usr/lib/python2.7/dist-packages/gunicorn/util.py", line 362, in import_app
    __import__(module)
  File "/home/js345/yumbon/cteemo/flask-user-api/app.py", line 51, in <module>
    @app.errorhandler(InvalidAPIUsage)
NameError: name 'InvalidAPIUsage' is not defined
Traceback (most recent call last):
  File "/usr/lib/python2.7/dist-packages/gunicorn/arbiter.py", line 473, in spawn_worker
    worker.init_process()
  File "/usr/lib/python2.7/dist-packages/gunicorn/workers/base.py", line 100, in init_process
    self.wsgi = self.app.wsgi()
  File "/usr/lib/python2.7/dist-packages/gunicorn/app/base.py", line 115, in wsgi
    self.callable = self.load()
  File "/usr/lib/python2.7/dist-packages/gunicorn/app/wsgiapp.py", line 33, in load
    return util.import_app(self.app_uri)
  File "/usr/lib/python2.7/dist-packages/gunicorn/util.py", line 362, in import_app
    __import__(module)
  File "/home/js345/yumbon/cteemo/flask-user-api/app.py", line 51, in <module>
    @app.errorhandler(InvalidAPIUsage)
NameError: name 'InvalidAPIUsage' is not defined
